Workbook

Sheet Detailed Product w Size & Prici
A1: Sku Number | B1: Count of Reviews (posted) | C1: Avg Star Rating | D1: VPC | E1: VPC 1 | F1: VPC 2 | G1: VCP Count of Reviews | H1: VPC Avg Star Rating | I1: Count of 'collection' Reviews | J1: Theme | K1: Customer Description | L1: Sale Price | M1: Regular Price | N1: Specialty Brand | O1: Proprietary (P) | P1: Collection Copy | Q1: Mattress Designation | R1: Mattress Size | S1: Mattress Type | T1: Pressure Relief | U1: Sleep Position | V1: Support Level | W1: Temperature Management | X1: Comfort | Y1: Image 1 | Z1: Image 2 | AA1: Base product link | AB1: Actual variant link
A2: 50000543 | J2: CASPER CLOUD ONE | K2: TWX CASPER CLOUD ONE | L2: 879 | M2: 1099 | N2: CASPER | Q2: Adult | R2: Twin XL | S2: Foam | T2: 3-Superior | U2: Side/Back/Stomach | V2: 3-Superior | W2: 2-Good | X2: Medium | Y2: =IFERROR(VLOOKUP(A2,Sheet3!B:H,6,false),VLOOKUP(J2,Sheet2!A:C,2,false)) -> https://assets.roomstogo.com/product/casper-cloud-one-twin-xl-mattress_50000543_image-item | Z2: =IFERROR(VLOOKUP(A2,Sheet3!B:H,7,false),VLOOKUP(J2,Sheet2!A:C,3,false)) -> https://assets.roomstogo.com/product/casper-cloud-one-twin-xl-mattress_50000543_alt-image-1
A3: 50000579 | J3: CASPER SNOW 2.0 | K3: TWXL CASPER SNOW 2.0 | L3: 1595 | M3: 1995 | N3: CASPER | P3: Casper signature cooling hybrid mattress. Specialty cool-to-the-touch fibers give an instantly refreshing feel. Phase Change Materialinstantly pulls heat away whileHeatDeleteT Bandsremove excess body heat to help yousleep 5 cooler all night long. Soothe Memory Foam conforms to the body and gently eases you into deep sleep. Zoned Support helps keep your spine in alignment with firmer foam under the hips, waist and lower back. Individually pocketed Flex Coils reduce motion transfer and boost support. | Q3: Adult | R3: Twin XL | S3: Hybrid | T3: 3-Superior | U3: Side/Back/Stomach | V3: 3-Superior | W3: 4-Premier | X3: Medium | Y3: =IFERROR(VLOOKUP(A3,Sheet3!B:H,6,false),VLOOKUP(J3,Sheet2!A:C,2,false)) -> https://assets.roomstogo.com/product/casper-snow-20-twin-xl-mattress_50000579_image-item | Z3: =IFERROR(VLOOKUP(A3,Sheet3!B:H,7,false),VLOOKUP(J3,Sheet2!A:C,3,false)) -> https://assets.roomstogo.com/product/casper-snow-20-twin-xl-mattress_50000579_alt-image-1
A4: 50000581 | B4: 1 | C4: 5 | D4: Mattress Only~Casper Snow Max | E4: Mattress Only | F4: Casper Snow Max | G4: 380 | H4: 4.42 | I4: 379 | J4: CASPER SNOW MAX | K4: TWXL CASPER SNOW MAX | L4: 2595 | M4: 3245 | N4: CASPER | P4: Ultimate cooling hybrid mattress. Specialty cool-to-the-touch fibers give an instantly refreshing feel. Phase Change MaterialandHeatDeleteT Bands remove excess body heat and help yousleep 6 cooler all night long. Precision-cut foam and encased coils for a breathable and supportive medium-soft feel. Ultra-supportive Align Memory Foam keeps you aligned for your deepest sleep. Firmer center foam cradles your body while giving added support to your hips, waist and lower back. Individually pocketed Flex Coils flex reduce motion transfer and boost support. | Q4: Adult | R4: Twin XL | S4: Hybrid | T4: 4-Premier | U4: Side/Back | V4: 3-Superior | W4: 5-Ultimate | X4: Soft | Y4: =IFERROR(VLOOKUP(A4,Sheet3!B:H,6,false),VLOOKUP(J4,Sheet2!A:C,2,false)) -> https://assets.roomstogo.com/product/casper-snow-max-twin-xl-mattress_50000581_image-item | Z4: =IFERROR(VLOOKUP(A4,Sheet3!B:H,7,false),VLOOKUP(J4,Sheet2!A:C,3,false)) -> https://assets.roomstogo.com/product/casper-snow-max-twin-xl-mattress_50000581_alt-image-1
A5: 50000682 | J5: CASPER ONYX 2.0 | K5: TWXL CASPER ONYX 2.0 | L5: 699 | M5: 799 | N5: CASPER | O5: P | P5: The Casper Onyx mattress is designed with 3 layers of foam for comfort, breathability and support. Obsessively engineered by Casper's award-winning research and development team, this mattress contains Breathe Flex Foam for support and pressure relief & Breathe Foam for air flow that pairs breathability with softness for all-night comfort. Key FeaturesA cozy knit cover designed with added stretch so you can experience all the comfort your mattress has to offer. Features a top layer of Breathe Flex Foam that's both responsive and breathable to soothe you to sleep with the perfect bit of bounce. A firm Casper Core base provides long-lasting support while preventing sinking and sagging. Foams are certified by the CertiPUR-US program, meaning they are made without ozone depleting chemicals and regulated by the Consumer Product Safety Commission Low VOC Volatile Organic Compound emissions for indoor air quality less than 0.5 parts per million. | Q5: Adult | R5: Twin XL | S5: Foam | T5: 2-Good | U5: Side/Back/Stomach | V5: 2-Good | W5: 2-Good | X5: Medium | Y5: =IFERROR(VLOOKUP(A5,Sheet3!B:H,6,false),VLOOKUP(J5,Sheet2!A:C,2,false)) -> https://assets.roomstogo.com/product/casper-onyx-20-twin-xl-mattress_50000682_image-item | Z5: =IFERROR(VLOOKUP(A5,Sheet3!B:H,7,false),VLOOKUP(J5,Sheet2!A:C,3,false)) -> https://assets.roomstogo.com/product/casper-onyx-20-twin-xl-mattress_50000682_alt-image-1
A6: 50001773 | J6: SMART MATCH 2.0 | K6: TWX SMART MATCH 2.0 | L6: 1077 | M6: 3199 | N6: KINGSDOWN | R6: Twin XL | S6: Innerspring | T6: 4-Premier | U6: Side/Back/Stomach | V6: 4-Premier | W6: 3-Superior | X6: Medium | Y6: =IFERROR(VLOOKUP(A6,Sheet3!B:H,6,false),VLOOKUP(J6,Sheet2!A:C,2,false)) -> https://assets.roomstogo.com/product/kingsdown-smart-match-20-twin-xl-mattress_50001773_image-item | Z6: =IFERROR(VLOOKUP(A6,Sheet3!B:H,7,false),VLOOKUP(J6,Sheet2!A:C,3,false)) -> https://assets.roomstogo.com/product/kingsdown-smart-match-20-twin-xl-mattress_50001773_alt-image-1
A7: 50007460 | B7: 332 | C7: 4.48 | D7: Mattress Only~Adapt 2.0 Medium | E7: Mattress Only | F7: Adapt 2.0 Medium | G7: 346 | H7: 4.43 | I7: 14 | J7: ADAPT 2.0 MEDIUM | K7: TWXL ADAPT MEDIUM | L7: 1699 | M7: 1699 | N7: TEMPURPEDIC | P7: .Superior cool-to-the-touch feel with a premium knit cover..TEMPUR-Material provides one-of-a-kind, body-conforming support by responding to your body's weight, shape, and temperature to help reduce aches and pains..A second layer of TEMPUR-Material absorbs motion to help minimize disruptions caused by movement from partners, pets, or kids. | Q7: Adult | R7: Twin XL | S7: Foam | T7: 4-Premier | U7: Side/Back/Stomach | V7: 4-Premier | W7: 4-Premier | X7: Medium | Y7: =IFERROR(VLOOKUP(A7,Sheet3!B:H,6,false),VLOOKUP(J7,Sheet2!A:C,2,false)) -> https://assets.roomstogo.com/product/tempur-pedic-adapt-20-medium-twin-xl-mattress_50007460_image-item | Z7: =IFERROR(VLOOKUP(A7,Sheet3!B:H,7,false),VLOOKUP(J7,Sheet2!A:C,3,false)) -> https://assets.roomstogo.com/product/tempur-pedic-adapt-20-medium-twin-xl-mattress_50007460_alt-image-1
A8: 50007472 | B8: 2576 | C8: 4.2 | D8: Mattress Only~Adapt 2.0 Medium Hybrid | E8: Mattress Only | F8: Adapt 2.0 Medium Hybrid | G8: 2587 | H8: 4.2 | I8: 11 | J8: ADAPT 2.0 MEDIUM HYBRID | K8: TWXL ADAPT MEDIUM HYBRID | L8: 1999 | M8: 1999 | N8: TEMPURPEDIC | P8: .Superior cool-to-the-touch feel with a premium knit cover..TEMPUR-Material provides one-of-a-kind, body-conforming support by responding to your body's weight, shape, and temperature to help reduce aches and pains..A second layer of TEMPUR-Material absorbs motion to help minimize disruptions caused by movement from partners, pets, or kids..Hybrid technology combines premium innersprings with TEMPUR-Material to deliver the right combination of pressure relief and support. | Q8: Adult | R8: Twin XL | S8: Hybrid | T8: 4-Premier | U8: Side/Back/Stomach | V8: 4-Premier | W8: 4-Premier | X8: Medium | Y8: =IFERROR(VLOOKUP(A8,Sheet3!B:H,6,false),VLOOKUP(J8,Sheet2!A:C,2,false)) -> https://assets.roomstogo.com/product/tempur-pedic-adapt-20-medium-hybrid-twin-xl-mattress_50007472_image-item | Z8: =IFERROR(VLOOKUP(A8,Sheet3!B:H,7,false),VLOOKUP(J8,Sheet2!A:C,3,false)) -> https://assets.roomstogo.com/product/tempur-pedic-adapt-20-medium-hybrid-twin-xl-mattress_50007472_alt-image-1
A9: 50007484 | B9: 237 | C9: 4.6 | D9: Mattress Only~Proadapt 2.0 Firm | E9: Mattress Only | F9: Proadapt 2.0 Firm | G9: 245 | H9: 4.62 | I9: 8 | J9: PROADAPT 2.0 FIRM | K9: TWXL PROADAPT FIRM | L9: 2899 | M9: 2899 | N9: TEMPURPEDIC | P9: .The removable, machine-washable, and cool-to-the-touch SmartClimate cover features heat-absorbing fibers, drawing heat away from the body for added cooling comfort..Ventilated Advanced Relief Material provides pressure relief and added ventilation for increased airflow..TEMPUR-Material provides one-of-a-kind, body-conforming support by responding to your body's weight, shape, and temperature. | Q9: Adult | R9: Twin XL | S9: Foam | T9: 4-Premier | U9: Stomach/Back | V9: 5-Ultimate | W9: 4-Premier | X9: Firm | Y9: =IFERROR(VLOOKUP(A9,Sheet3!B:H,6,false),VLOOKUP(J9,Sheet2!A:C,2,false)) -> https://assets.roomstogo.com/product/tempur-pedic-proadapt-20-firm-twin-xl-mattress_50007484_image-item | Z9: =IFERROR(VLOOKUP(A9,Sheet3!B:H,7,false),VLOOKUP(J9,Sheet2!A:C,3,false)) -> https://assets.roomstogo.com/product/tempur-pedic-proadapt-20-firm-twin-xl-mattress_50007484_alt-image-1
A10: 50007511 | B10: 302 | C10: 4.48 | D10: Mattress Only~Probreeze 2.0 Medium Hybrid | E10: Mattress Only | F10: Probreeze 2.0 Medium Hybrid | G10: 306 | H10: 4.48 | I10: 4 | J10: PROBREEZE 2.0 MEDIUM HYBRID | K10: TWXL PROBREEZE MED HYBRID | L10: 3899 | M10: 3899 | N10: TEMPURPEDIC | P10: Experience all-night cooling with the all-new TEMPUR-ProBreeze mattress. Features a removable, machine-washable cover with heat-absorbing fibers that provide cooling comfort. Premium hybrid technology combines over 1,000 innersprings with Tempur-Pedic's pressure relieving and cooling materials. Delivers exceptional support and ensures cool and comfortable sleep every night. | Q10: Adult | R10: Twin XL | S10: Hybrid | T10: 4-Premier | U10: Side/Back/Stomach | V10: 5-Ultimate | W10: 5-Ultimate | X10: Medium | Y10: =IFERROR(VLOOKUP(A10,Sheet3!B:H,6,false),VLOOKUP(J10,Sheet2!A:C,2,false)) -> https://assets.roomstogo.com/product/tempur-pedic-probreeze-20-medium-hybrid-twin-xl-mattress_50007511_image-item | Z10: =IFERROR(VLOOKUP(A10,Sheet3!B:H,7,false),VLOOKUP(J10,Sheet2!A:C,3,false)) -> https://assets.roomstogo.com/product/tempur-pedic-probreeze-20-medium-hybrid-twin-xl-mattress_50007511_image-item
A11: 50007523 | B11: 5214 | C11: 4.27 | D11: Mattress Only~Proadapt 2.0 Medium | E11: Mattress Only | F11: Proadapt 2.0 Medium | G11: 5219 | H11: 4.27 | I11: 5 | J11: PROADAPT 2.0 MEDIUM | K11: TWXL PROADAPT MEDIUM | L11: 2899 | M11: 2899 | N11: TEMPURPEDIC | P11: .The removable, machine-washable, and cool-to-the-touch SmartClimate cover features heat-absorbing fibers, drawing heat away from the body for added cooling comfort..Ventilated Advanced Relief Material provides pressure relief and added ventilation for increased airflow..TEMPUR-Material provides one-of-a-kind, body-conforming support by responding to your body's weight, shape, and temperature. | Q11: Adult | R11: Twin XL | S11: Foam | T11: 4-Premier | U11: Side/Back/Stomach | V11: 5-Ultimate | W11: 4-Premier | X11: Medium | Y11: =IFERROR(VLOOKUP(A11,Sheet3!B:H,6,false),VLOOKUP(J11,Sheet2!A:C,2,false)) -> https://assets.roomstogo.com/product/tempur-pedic-proadapt-20-medium-twin-xl-mattress_50007523_image-item | Z11: =IFERROR(VLOOKUP(A11,Sheet3!B:H,7,false),VLOOKUP(J11,Sheet2!A:C,3,false)) -> https://assets.roomstogo.com/product/tempur-pedic-proadapt-20-medium-twin-xl-mattress_50007523_alt-image-1
A12: 50007535 | B12: 72 | C12: 4.31 | D12: Mattress Only~Proadapt 2.0 Soft | E12: Mattress Only | F12: Proadapt 2.0 Soft | G12: 77 | H12: 4.19 | I12: 5 | J12: PROADAPT 2.0 SOFT | K12: TWXL PROADAPT SOFT | L12: 2899 | M12: 2899 | N12: TEMPURPEDIC | P12: .The removable, machine-washable, and cool-to-the-touch SmartClimate cover features heat-absorbing fibers, drawing heat away from the body for added cooling comfort..Specially ventilated TEMPUR-Material delivers additional airflow and breathability, while providing pressure relief and motion absorption..Advanced Relief Material is the most pressure-relieving material made by Tempur-Pedic and conforms to your body for ultimate comfort. | Q12: Adult | R12: Twin XL | S12: Foam | T12: 5-Ultimate | U12: Side/Back | V12: 5-Ultimate | W12: 4-Premier | X12: Soft | Y12: =IFERROR(VLOOKUP(A12,Sheet3!B:H,6,false),VLOOKUP(J12,Sheet2!A:C,2,false)) -> https://assets.roomstogo.com/product/tempur-pedic-proadapt-20-soft-twin-xl-mattress_50007535_image-item | Z12: =IFERROR(VLOOKUP(A12,Sheet3!B:H,7,false),VLOOKUP(J12,Sheet2!A:C,3,false)) -> https://assets.roomstogo.com/product/tempur-pedic-proadapt-20-soft-twin-xl-mattress_50007535_alt-image-1
A13: 50007559 | B13: 960 | C13: 4.38 | D13: Mattress Only~Proadapt 2.0 Medium Hybrid | E13: Mattress Only | F13: Proadapt 2.0 Medium Hybrid | G13: 975 | H13: 4.38 | I13: 15 | J13: PROADAPT 2.0 MEDIUM HYBRID | K13: TWXL PROADAPT MEDIUM HYBRID | L13: 2899 | M13: 2899 | N13: TEMPURPEDIC | P13: .The removable, machine-washable, and cool-to-the-touch SmartClimate cover features heat-absorbing fibers, drawing heat away from the body for added cooling comfort..Specially ventilated TEMPUR-Material delivers additional airflow and breathability, while providing pressure relief and motion absorption..Advanced Relief Material is the most pressure-relieving material made by Tempur-Pedic and contours to your body for ultimate comfort. .Hybrid technology mixes premium innersprings with one-of-a-kind Tempur-Pedic materials to deliver the right combination of relief and support. | Q13: Adult | R13: Twin XL | S13: Hybrid | T13: 4-Premier | U13: Side/Back/Stomach | V13: 5-Ultimate | W13: 4-Premier | X13: Medium | Y13: =IFERROR(VLOOKUP(A13,Sheet3!B:H,6,false),VLOOKUP(J13,Sheet2!A:C,2,false)) -> https://assets.roomstogo.com/product/tempur-pedic-proadapt-20-medium-hybrid-twin-xl-mattress_50007559_image-item | Z13: =IFERROR(VLOOKUP(A13,Sheet3!B:H,7,false),VLOOKUP(J13,Sheet2!A:C,3,false)) -> https://assets.roomstogo.com/product/tempur-pedic-proadapt-20-medium-hybrid-twin-xl-mattress_50007559_alt-image-1
A14: 50007561 | B14: 1233 | C14: 4.24 | D14: Mattress Only~Luxeadapt 2.0 Soft | E14: Mattress Only | F14: Luxeadapt 2.0 Soft | G14: 1234 | H14: 4.24 | I14: 1 | J14: LUXEADAPT 2.0 SOFT | K14: TWXL LUXEADAPT SOFT | L14: 4199 | M14: 4199 | N14: TEMPURPEDIC | P14: .The removable, machine-washable, and cool-to-the-touch SmartClimate cover features heat-absorbing fibers, drawing heat away from the body for added cooling comfort..Specially ventilated TEMPUR-Material delivers additional airflow and breathability, while providing pressure relief and motion absorption..Advanced Relief Material is the most pressure-relieving material made by Tempur-Pedic and contours to your body for ultimate comfort. .An ergonomic 5-zone support layer conforms to your body for targeted support in the spine, hips, and shoulders for personalized comfort. | Q14: Adult | R14: Twin XL | S14: Foam | T14: 5-Ultimate | U14: Side/Back | V14: 5-Ultimate | W14: 4-Premier | X14: Soft | Y14: =IFERROR(VLOOKUP(A14,Sheet3!B:H,6,false),VLOOKUP(J14,Sheet2!A:C,2,false)) -> https://assets.roomstogo.com/product/tempur-pedic-luxeadapt-20-soft-twin-xl-mattress_50007561_image-item | Z14: =IFERROR(VLOOKUP(A14,Sheet3!B:H,7,false),VLOOKUP(J14,Sheet2!A:C,3,false)) -> https://assets.roomstogo.com/product/tempur-pedic-luxeadapt-20-soft-twin-xl-mattress_50007561_alt-image-1
A15: 50007585 | B15: 125 | C15: 4.61 | D15: Mattress Only~Luxeadapt 2.0 Medium Hybrid | E15: Mattress Only | F15: Luxeadapt 2.0 Medium Hybrid | G15: 129 | H15: 4.62 | I15: 4 | J15: LUXEADAPT 2.0 MEDIUM HYBRID | K15: TWXL LUXEADAPT MEDIUM HYBRID | L15: 4199 | M15: 4199 | N15: TEMPURPEDIC | P15: .The removable, machine-washable, and cool-to-the-touch SmartClimate cover features heat-absorbing fibers, drawing heat away from the body for added cooling comfort..Specially ventilated TEMPUR-Material delivers additional airflow and breathability, while providing pressure relief and motion absorption..Advanced Relief Material is the most pressure-relieving material made by Tempur-Pedic and contours to your body for ultimate comfort. .Hybrid technology mixes premium innersprings with a proprietary hybrid material to deliver a lighter, more-responsive feel that helps support any sleep position. | Q15: Adult | R15: Twin XL | S15: Hybrid | T15: 5-Ultimate | U15: Side/Back/Stomach | V15: 5-Ultimate | W15: 4-Premier | X15: Medium | Y15: =IFERROR(VLOOKUP(A15,Sheet3!B:H,6,false),VLOOKUP(J15,Sheet2!A:C,2,false)) -> https://assets.roomstogo.com/product/tempur-pedic-luxeadapt-20-medium-hybrid-twin-xl-mattress_50007585_image-item | Z15: =IFERROR(VLOOKUP(A15,Sheet3!B:H,7,false),VLOOKUP(J15,Sheet2!A:C,3,false)) -> https://assets.roomstogo.com/product/tempur-pedic-luxeadapt-20-medium-hybrid-twin-xl-mattress_50007585_alt-image-1
A16: 50007624 | B16: 434 | C16: 4.54 | D16: Mattress Only~Luxebreeze 2.0 Firm | E16: Mattress Only | F16: Luxebreeze 2.0 Firm | G16: 440 | H16: 4.54 | I16: 6 | J16: LUXEBREEZE 2.0 FIRM | K16: TWXL LUXEBREEZE FIRM | L16: 5199 | M16: 5199 | N16: TEMPURPEDIC | P16: The all-new TEMPUR-LuxeBreeze mattress feels up to 10 cooler. Features advanced Pure Cool Plus material designed to pull heat away from the body so even the hottest sleepers can stay cool throughout the night. One-of-a-kind Tempur-Pedic Ventilated Advanced Relief material increases airflow throughout the mattress for a deeper, more restful sleep. | Q16: Adult | R16: Twin XL | S16: Foam | T16: 5-Ultimate | U16: Stomach/Back | V16: 5-Ultimate | W16: 5-Ultimate | X16: Firm | Y16: =IFERROR(VLOOKUP(A16,Sheet3!B:H,6,false),VLOOKUP(J16,Sheet2!A:C,2,false)) -> https://assets.roomstogo.com/product/tempur-pedic-luxebreeze-20-firm-twin-xl-mattress_50007624_image-item | Z16: =IFERROR(VLOOKUP(A16,Sheet3!B:H,7,false),VLOOKUP(J16,Sheet2!A:C,3,false)) -> https://assets.roomstogo.com/product/tempur-pedic-luxebreeze-20-firm-twin-xl-mattress_50007624_image-item
A17: 50009870 | J17: TUFT & NEEDLE STITCH TN3.1 | K17: TWX T&N TN3.1 | L17: 797 | M17: 999 | N17: TUFT & NEEDLE | O17: P | Q17: Adult | R17: Twin XL | S17: Hybrid | T17: 3-Superior | U17: Side/Back/Stomach | V17: 3-Superior | W17: 3-Superior | X17: Medium | Y17: =IFERROR(VLOOKUP(A17,Sheet3!B:H,6,false),VLOOKUP(J17,Sheet2!A:C,2,false)) -> https://assets.roomstogo.com/product/tuft-needle-stitch-tn31-twin-xl-mattress_50009870_image-item | Z17: =IFERROR(VLOOKUP(A17,Sheet3!B:H,7,false),VLOOKUP(J17,Sheet2!A:C,3,false)) -> https://assets.roomstogo.com/product/tuft-needle-stitch-tn31-twin-xl-mattress_50009870_alt-image-1
A18: 50009882 | J18: TUFT & NEEDLE STITCH TN5.1 | K18: TWX T&N TN5.1 | L18: 795 | M18: 1399 | N18: TUFT & NEEDLE | O18: P | Q18: Adult | R18: Twin XL | S18: Hybrid | T18: 4-Premier | U18: Stomach/Back | V18: 4-Premier | W18: 4-Premier | X18: Firm | Y18: =IFERROR(VLOOKUP(A18,Sheet3!B:H,6,false),VLOOKUP(J18,Sheet2!A:C,2,false)) -> https://assets.roomstogo.com/product/tuft-needle-stitch-tn51-twin-xl-mattress_50009882_image-item | Z18: =IFERROR(VLOOKUP(A18,Sheet3!B:H,7,false),VLOOKUP(J18,Sheet2!A:C,3,false)) -> https://assets.roomstogo.com/product/tuft-needle-stitch-tn51-twin-xl-mattress_50009882_alt-image-1
A19: 50009907 | J19: TUFT & NEEDLE STITCH TN9.1 | K19: TWX T&N TN9.1 | L19: 1597 | M19: 2099 | N19: TUFT & NEEDLE | O19: P | Q19: Adult | R19: Twin XL | S19: Hybrid | T19: 5-Ultimate | U19: Side/Back | V19: 4-Premier | W19: 4-Premier | X19: Soft | Y19: =IFERROR(VLOOKUP(A19,Sheet3!B:H,6,false),VLOOKUP(J19,Sheet2!A:C,2,false)) -> https://assets.roomstogo.com/product/tuft-needle-stitch-tn91-twin-xl-mattress_50009907_image-item | Z19: =IFERROR(VLOOKUP(A19,Sheet3!B:H,7,false),VLOOKUP(J19,Sheet2!A:C,3,false)) -> https://assets.roomstogo.com/product/tuft-needle-stitch-tn91-twin-xl-mattress_50009907_alt-image-1
A20: 50009933 | J20: TUFT & NEEDLE TN1 | K20: TWX T&N TN1 | L20: 577 | M20: 699 | N20: TUFT & NEEDLE | O20: P | P20: Reclaim your nights and wake refreshed for your days with the Tuft & Needle TN1 12 Firm mattress. Available in a standard flat-mattress construction, this mattress offers innovative cooling, responsive pressure relief, and the bounce back support of T&N Adaptive foam, so you can sink deeply into sleep-but never into your mattress. Unlike memory foam, Tuft & Needle's T&N Adaptive foam doesn't sink under your weight. Instead, it keeps you lifted while contouring to relieve pressure where you need it most. Rest easy as this ventilated foam helps channel airflow through the mattress and a breathable cover helps you sleep comfortably. Plus, feel cool as T&N AdaptiveCool gel foam technology, designed to help absorb heat, is ribboned across the center-third of the mattress to promote optimal cooling. With the addition of comfortable support foams, each Tuft & Needle TN1 12 Firm flat-mattress protects your rest so you can wake up refreshed and ready for the day. | Q20: Adult | R20: Twin XL | S20: Foam | T20: 2-Good | U20: Stomach/Back | V20: 2-Good | W20: 2-Good | X20: Firm | Y20: =IFERROR(VLOOKUP(A20,Sheet3!B:H,6,false),VLOOKUP(J20,Sheet2!A:C,2,false)) -> https://assets.roomstogo.com/product/tuft-needle-tn1-twin-xl-mattress_50009933_image-item | Z20: =IFERROR(VLOOKUP(A20,Sheet3!B:H,7,false),VLOOKUP(J20,Sheet2!A:C,3,false)) -> https://assets.roomstogo.com/product/tuft-needle-tn1-twin-xl-mattress_50009933_alt-image-1
A21: 50010570 | J21: MOLECULE CORE | K21: TWXL MOLECULE CORE | L21: 447 | M21: 949 | N21: MOLECULE | R21: Twin XL | S21: Foam | T21: 3-Superior | U21: Side/Back/Stomach | V21: 3-Superior | W21: 3-Superior | X21: Medium | Y21: =IFERROR(VLOOKUP(A21,Sheet3!B:H,6,false),VLOOKUP(J21,Sheet2!A:C,2,false)) -> https://assets.roomstogo.com/product/molecule-core-twin-xl-mattress_50010570_image-item | Z21: =IFERROR(VLOOKUP(A21,Sheet3!B:H,7,false),VLOOKUP(J21,Sheet2!A:C,3,false)) -> https://assets.roomstogo.com/product/molecule-core-twin-xl-mattress_50010570_alt-image-1
A22: 50010671 | B22: 2 | C22: 3 | D22: Mattress Only~Broad Peak Medium Hybrid | E22: Mattress Only | F22: Broad Peak Medium Hybrid | G22: 192 | H22: 4.4 | I22: 190 | J22: BROAD PEAK MEDIUM HYBRID | K22: TWXL BROAD PEAK | L22: 695 | M22: 849.99 | N22: BEAUTYREST SELECT | O22: P | P22: Developed by the pioneer of the hybrid mattress, the new Beautyrest Select Hybrid line offers consistent that conforms to your body, allowing you to find your optimal sleep position. The superior stretch and recovery surface adapts with you throughout the night, enabling you to engage more closely with the pressure relieving memory foams for a deep, easy sleep. This unique construction enhances the benefits of both our Pocketed Coil Technology and gel memory foams to provide comfort and breathability. | Q22: Adult | R22: Twin XL | S22: Hybrid | T22: 3-Superior | U22: Side/Back/Stomach | V22: 3-Superior | W22: 3-Superior | X22: Medium | Y22: =IFERROR(VLOOKUP(A22,Sheet3!B:H,6,false),VLOOKUP(J22,Sheet2!A:C,2,false)) -> https://assets.roomstogo.com/product/beautyrest-select-broad-peak-medium-hybrid-twin-xl-mattress_50010671_image-item | Z22: =IFERROR(VLOOKUP(A22,Sheet3!B:H,7,false),VLOOKUP(J22,Sheet2!A:C,3,false)) -> https://assets.roomstogo.com/product/beautyrest-select-broad-peak-medium-hybrid-twin-xl-mattress_50010671_alt-image-1
A23: 50011053 | J23: BAY DREAMER | K23: TWX BAY DREAMER | L23: 445 | M23: 549.99 | N23: TOMMY BAHAMA | O23: P | Q23: Kid | R23: Twin XL | S23: Innerspring | T23: 2-Good | U23: Side/Back | V23: 4-Premier | W23: 2-Good | X23: Soft | Y23: =IFERROR(VLOOKUP(A23,Sheet3!B:H,6,false),VLOOKUP(J23,Sheet2!A:C,2,false)) -> https://assets.roomstogo.com/product/tommy-bahama-bay-dreamer-twin-mattress_50111055_image-item | Z23: =IFERROR(VLOOKUP(A23,Sheet3!B:H,7,false),VLOOKUP(J23,Sheet2!A:C,3,false)) -> https://assets.roomstogo.com/product/tommy-bahama-bay-dreamer-twin-mattress_50111055_alt-image-1
A24: 50011065 | J24: MAKE WAVES | K24: TWX MAKE WAVES | L24: 495 | M24: 599.99 | N24: TOMMY BAHAMA | O24: P | Q24: Kid | R24: Twin XL | S24: Hybrid | T24: 2-Good | U24: Stomach/Back | V24: 4-Premier | W24: 2-Good | X24: Firm | Y24: =IFERROR(VLOOKUP(A24,Sheet3!B:H,6,false),VLOOKUP(J24,Sheet2!A:C,2,false)) -> https://assets.roomstogo.com/product/tommy-bahama-make-waves-twin-mattress_50111067_image-item | Z24: =IFERROR(VLOOKUP(A24,Sheet3!B:H,7,false),VLOOKUP(J24,Sheet2!A:C,3,false)) -> https://assets.roomstogo.com/product/tommy-bahama-make-waves-twin-mattress_50111067_alt-image-1
A25: 50011077 | J25: SEASIDE SERENITY | K25: TWX SEASIDE SERENITY | L25: 595 | M25: 699.99 | N25: TOMMY BAHAMA | O25: P | Q25: Kid | R25: Twin XL | S25: Innerspring | T25: 2-Good | U25: Side/Back/Stomach | V25: 4-Premier | W25: 2-Good | X25: Medium | Y25: =IFERROR(VLOOKUP(A25,Sheet3!B:H,6,false),VLOOKUP(J25,Sheet2!A:C,2,false)) -> https://assets.roomstogo.com/product/tommy-bahama-seaside-serenity-twin-mattress_50111079_image-item | Z25: =IFERROR(VLOOKUP(A25,Sheet3!B:H,7,false),VLOOKUP(J25,Sheet2!A:C,3,false)) -> https://assets.roomstogo.com/product/tommy-bahama-seaside-serenity-twin-mattress_50111079_alt-image-1
A26: 50011344 | B26: 1 | C26: 5 | D26: Mattress Only~Forester | E26: Mattress Only | F26: Forester | G26: 10 | H26: 4.2 | I26: 9 | J26: FORESTER | K26: TWX FORESTER | L26: 647 | M26: 849.99 | N26: THERAPEDIC | O26: P | Q26: Adult | R26: Twin XL | S26: Innerspring | T26: 2-Good | U26: Stomach/Back | V26: 3-Superior | W26: 2-Good | X26: Extra Firm | Y26: =IFERROR(VLOOKUP(A26,Sheet3!B:H,6,false),VLOOKUP(J26,Sheet2!A:C,2,false)) -> https://assets.roomstogo.com/product/therapedic-forester-twin-xl-mattress_50011344_image-item | Z26: =IFERROR(VLOOKUP(A26,Sheet3!B:H,7,false),VLOOKUP(J26,Sheet2!A:C,3,false)) -> https://assets.roomstogo.com/product/therapedic-forester-twin-xl-mattress_50011344_alt-image-1
A27: 50011368 | J27: DARLINGTON | K27: TWX DARLINGTON | L27: 547 | M27: 649.99 | N27: THERAPEDIC | O27: P | Q27: Adult | R27: Twin XL | S27: Innerspring | T27: 2-Good | U27: Side/Back/Stomach | V27: 2-Good | W27: 3-Superior | X27: Medium | Y27: =IFERROR(VLOOKUP(A27,Sheet3!B:H,6,false),VLOOKUP(J27,Sheet2!A:C,2,false)) -> https://assets.roomstogo.com/product/therapedic-darlington-twin-xl-mattress_50011368_image-item | Z27: =IFERROR(VLOOKUP(A27,Sheet3!B:H,7,false),VLOOKUP(J27,Sheet2!A:C,3,false)) -> https://assets.roomstogo.com/product/therapedic-darlington-twin-xl-mattress_50011368_alt-image-1
A28: 50011382 | J28: HASTINGS | K28: TWXL HASTINGS | L28: 627 | M28: 949.99 | N28: THERAPEDIC HYBRID | O28: P | R28: Twin XL | S28: Hybrid | T28: 2-Good | U28: Side/Back | V28: 3-Superior | W28: 3-Superior | X28: Soft | Y28: =IFERROR(VLOOKUP(A28,Sheet3!B:H,6,false),VLOOKUP(J28,Sheet2!A:C,2,false)) -> https://assets.roomstogo.com/product/therapedic-hastings-twin-xl-mattress_50011382_image-item | Z28: =IFERROR(VLOOKUP(A28,Sheet3!B:H,7,false),VLOOKUP(J28,Sheet2!A:C,3,false)) -> https://assets.roomstogo.com/product/therapedic-hastings-twin-xl-mattress_50011382_alt-image-1
A29: 50011457 | J29: KAANAPALI | K29: TWXL KAANAPALI | L29: 1249.99 | M29: 1249.99 | N29: THERAPEDIC HYBRID | O29: P | Q29: Adult | R29: Twin XL | S29: Hybrid | T29: 3-Superior | U29: Stomach/Back | V29: 4-Premier | W29: 3-Superior | X29: Firm | Y29: =IFERROR(VLOOKUP(A29,Sheet3!B:H,6,false),VLOOKUP(J29,Sheet2!A:C,2,false)) -> https://assets.roomstogo.com/product/therapedic-kaanapali-twin-xl-mattress_50011457_image-item | Z29: =IFERROR(VLOOKUP(A29,Sheet3!B:H,7,false),VLOOKUP(J29,Sheet2!A:C,3,false)) -> https://assets.roomstogo.com/product/therapedic-kaanapali-twin-xl-mattress_50011457_alt-image-1
A30: 50011495 | B30: 1 | C30: 5 | D30: Mattress Only~Ledo | E30: Mattress Only | F30: Ledo | G30: 13 | H30: 3.92 | I30: 12 | J30: LEDO | K30: TWXL LEDO | L30: 1449.99 | M30: 1449.99 | N30: THERAPEDIC HYBRID | O30: P | Q30: Adult | R30: Twin XL | S30: Hybrid | T30: 4-Premier | U30: Side/Back/Stomach | V30: 4-Premier | W30: 3-Superior | X30: Medium | Y30: =IFERROR(VLOOKUP(A30,Sheet3!B:H,6,false),VLOOKUP(J30,Sheet2!A:C,2,false)) -> https://assets.roomstogo.com/product/therapedic-ledo-twin-xl-mattress_50011495_image-item | Z30: =IFERROR(VLOOKUP(A30,Sheet3!B:H,7,false),VLOOKUP(J30,Sheet2!A:C,3,false)) -> https://assets.roomstogo.com/product/therapedic-ledo-twin-xl-mattress_50011495_alt-image-1
A31: 50020862 | J31: CAPERTEE | K31: TWXL CAPERTEE | L31: 797 | M31: 1099.99 | N31: DREW & JONATHAN | O31: P | Q31: Adult | R31: Twin XL | S31: Innerspring | T31: 3-Superior | U31: Side/Back/Stomach | V31: 3-Superior | W31: 3-Superior | X31: Medium | Y31: =IFERROR(VLOOKUP(A31,Sheet3!B:H,6,false),VLOOKUP(J31,Sheet2!A:C,2,false)) -> https://assets.roomstogo.com/product/drew-jonathan-capertee-twin-xl-mattress_50020862_image-item | Z31: =IFERROR(VLOOKUP(A31,Sheet3!B:H,7,false),VLOOKUP(J31,Sheet2!A:C,3,false)) -> https://assets.roomstogo.com/product/drew-jonathan-capertee-twin-xl-mattress_50020862_alt-image-1
A32: 50020925 | J32: ARADA CANYON | K32: TWXL ARADA CANYON | L32: 1297 | M32: 1599.99 | N32: DREW & JONATHAN | O32: P | Q32: Adult | R32: Twin XL | S32: Innerspring | T32: 4-Premier | U32: Side/Back | V32: 3-Superior | W32: 3-Superior | X32: Soft | Y32: =IFERROR(VLOOKUP(A32,Sheet3!B:H,6,false),VLOOKUP(J32,Sheet2!A:C,2,false)) -> https://assets.roomstogo.com/product/drew-jonathan-arada-canyon-twin-xl-mattress_50020925_image-item | Z32: =IFERROR(VLOOKUP(A32,Sheet3!B:H,7,false),VLOOKUP(J32,Sheet2!A:C,3,false)) -> https://assets.roomstogo.com/product/drew-jonathan-arada-canyon-twin-xl-mattress_50020925_alt-image-1
A33: 50022210 | B33: 2 | C33: 5 | D33: Mattress Only~Oceana Mist | E33: Mattress Only | F33: Oceana Mist | G33: 28 | H33: 4.71 | I33: 26 | J33: OCEANA MIST | K33: TWX OCEANA MIST | L33: 377 | M33: 679.99 | N33: BEAUTYSLEEP | O33: P | P33: The Beauty Sleep Oceana Mist 11.5 Medium Hybrid mattress is designed for your lifestyle. With a smooth top panel, the Beauty Sleep Oceana Mist 11.5 Medium Hybrid mattress features AllCool Gel Foam and AllCool Gel Memory Foam that contours to your body for the ultimate pressure relief. Premium foams provide a responsive sleep surface for all-night comfort, support, airflow, and breathability. Plus, firm 815 Original Beauty Sleep Pocketed Coils provide consistent, supportive sleep at a value designed for your lifestyle. Medium Smooth Top Hybrid mattress. | Q33: Adult | R33: Twin XL | S33: Hybrid | T33: 2-Good | U33: Side/Back/Stomach | V33: 3-Superior | W33: 2-Good | X33: Medium | Y33: =IFERROR(VLOOKUP(A33,Sheet3!B:H,6,false),VLOOKUP(J33,Sheet2!A:C,2,false)) -> https://assets.roomstogo.com/product/beauty-sleep-oceana-mist-medium-hybrid-twin-xl-mattress_50022210_image-item | Z33: =IFERROR(VLOOKUP(A33,Sheet3!B:H,7,false),VLOOKUP(J33,Sheet2!A:C,3,false)) -> https://assets.roomstogo.com/product/beauty-sleep-oceana-mist-medium-hybrid-twin-xl-mattress_50022210_alt-image-8
A34: 50025747 | B34: 1 | C34: 1 | D34: Mattress Only~Level Three Plush | E34: Mattress Only | F34: Level Three Plush | G34: 13 | H34: 4.08 | I34: 12 | J34: LEVEL THREE PLUSH | K34: TWXL WORLD CLASS LEVEL THREE PLUSH | L34: 1329 | M34: 1329 | N34: BEAUTYREST WORLD CLASS | P34: Step up to a world class sleep experience with Beautyrest World Class. Provides cushy comfort that responds to movement with a soft-yet-supportive feel. InfiniCool MAX Technology adds advanced cooling with vertical cooling fibers. SurfaceTouch Gel Memory Foam is quilted into the sleep surface to unlock immediate, advanced comfort. World Class Relief HD Foam, featured in all level three Beautyrest mattresses, adapts to body temperature, providing responsive pressure relief. Beautyrest ActiveResponse MAX HD Memory Foam creates high-density contouring to help alleviate aches and pains. 1000-density Pocketed Coil Technology and higher density foams offer individualized support motion separation. | Q34: Adult | R34: Twin XL | S34: Innerspring | T34: 4-Premier | U34: Side/Back | V34: 4-Premier | W34: 4-Premier | X34: Soft | Y34: =IFERROR(VLOOKUP(A34,Sheet3!B:H,6,false),VLOOKUP(J34,Sheet2!A:C,2,false)) -> https://assets.roomstogo.com/product/beautyrest-world-class-level-three-plush-twin-xl-mattress_50025747_image-item | Z34: =IFERROR(VLOOKUP(A34,Sheet3!B:H,7,false),VLOOKUP(J34,Sheet2!A:C,3,false)) -> https://assets.roomstogo.com/product/beautyrest-world-class-level-three-plush-twin-xl-mattress_50025747_alt-image-13
A35: 50025759 | J35: LEVEL THREE MEDIUM PILLOWTOP | K35: TWXL WORLD CLASS LEVEL THREE MED PT | L35: 1529 | M35: 1529 | N35: BEAUTYREST WORLD CLASS | P35: Step up to a world class sleep experience with Beautyrest World Class. Provides medium support with just the right amount of pressure relief and cloud-like top layer. InfiniCool MAX Technology adds advanced cooling combined with natural lux fibers for added surface breathability. SurfaceTouch Gel Memory Foam is quilted into the sleep surface to unlock immediate, advanced comfort. GelTouch Foam helps provide comfort, support, airflow and breathability. World Class Relief HD Foam, featured in all level three Beautyrest mattresses, adapts to body temperature, providing responsive pressure relief. Beautyrest ActiveResponse MAX HD Memory Foam creates high-density contouring to help alleviate aches and pains. 1000-density Pocketed Coil Technology and higher density foams offer individualized support motion separation. | Q35: Adult | R35: Twin XL | S35: Innerspring | T35: 4-Premier | U35: Side/Back/Stomach | V35: 4-Premier | W35: 4-Premier | X35: Medium | Y35: =IFERROR(VLOOKUP(A35,Sheet3!B:H,6,false),VLOOKUP(J35,Sheet2!A:C,2,false)) -> https://assets.roomstogo.com/product/beautyrest-world-class-level-three-medium-pillow-top-twin-xl-mattress_50025759_image-item | Z35: =IFERROR(VLOOKUP(A35,Sheet3!B:H,7,false),VLOOKUP(J35,Sheet2!A:C,3,false)) -> https://assets.roomstogo.com/product/beautyrest-world-class-level-three-medium-pillow-top-twin-xl-mattress_50025759_alt-image-13
A36: 50025800 | J36: LEVEL FOUR PLUSH PILLOWTOP | K36: TWXL WORLD CLASS LEVEL FOUR PLUSH PT | L36: 1829 | M36: 1829 | N36: BEAUTYREST WORLD CLASS | P36: Step up to a world class sleep experience with Beautyrest World Class. Provides cushy comfort that responds to movement with a soft-yet-supportive feel and a cloud-like top layer. InfiniCool MAX Technology adds advanced cooling with vertical cooling fibers. Level Four mattresses feature twice the SurfaceTouch Gel Memory Foam, unlocking even more pressure relief right at the surface. World Class Relief HD Foam, featured in all level four Beautyrest mattresses, offers remarkable pressure relief that responds to your body. Beautyrest ActiveResponse MAX HD Memory Foam helps alleviate aches and pains withhigh-density contouring. 1000-density Pocketed Coil Technology and higher density foams offer individualized support motion separation. | Q36: Adult | R36: Twin XL | S36: Innerspring | T36: 5-Ultimate | U36: Side/Back | V36: 4-Premier | W36: 4-Premier | X36: Soft | Y36: =IFERROR(VLOOKUP(A36,Sheet3!B:H,6,false),VLOOKUP(J36,Sheet2!A:C,2,false)) -> https://assets.roomstogo.com/product/beautyrest-world-class-level-four-plush-pillow-top-twin-xl-mattress_50025800_image-item | Z36: =IFERROR(VLOOKUP(A36,Sheet3!B:H,7,false),VLOOKUP(J36,Sheet2!A:C,3,false)) -> https://assets.roomstogo.com/product/beautyrest-world-class-level-four-plush-pillow-top-twin-xl-mattress_50025800_alt-image-13
A37: 50028957 | J37: KERRY PARK | K37: TWX KERRY PARK | L37: 877 | M37: 1479 | N37: CORRECT COMFORT | O37: P | Q37: Adult | R37: Twin XL | S37: Innerspring | T37: 4-Premier | U37: Side/Back | V37: 3-Superior | W37: 3-Superior | X37: Extra Soft | Y37: =IFERROR(VLOOKUP(A37,Sheet3!B:H,6,false),VLOOKUP(J37,Sheet2!A:C,2,false)) -> https://assets.roomstogo.com/product/sealy-correct-comfort-kerry-park-twin-xl-mattress_50028957_image-item | Z37: =IFERROR(VLOOKUP(A37,Sheet3!B:H,7,false),VLOOKUP(J37,Sheet2!A:C,3,false)) -> https://assets.roomstogo.com/product/sealy-correct-comfort-kerry-park-twin-xl-mattress_50028957_alt-image-1
A38: 50028969 | B38: 1 | C38: 5 | D38: Mattress Only~Bradford Hill | E38: Mattress Only | F38: Bradford Hill | G38: 12 | H38: 4.83 | I38: 11 | J38: BRADFORD HILL | K38: TWX BRADFORD HILL | L38: 645 | M38: 749 | N38: CORRECT COMFORT | O38: P | Q38: Adult | R38: Twin XL | S38: Foam | T38: 3-Superior | U38: Side/Back/Stomach | V38: 3-Superior | W38: 2-Good | X38: Medium | Y38: =IFERROR(VLOOKUP(A38,Sheet3!B:H,6,false),VLOOKUP(J38,Sheet2!A:C,2,false)) -> https://assets.roomstogo.com/product/sealy-correct-comfort-bradford-hill-twin-xl-mattress_50028969_image-item | Z38: =IFERROR(VLOOKUP(A38,Sheet3!B:H,7,false),VLOOKUP(J38,Sheet2!A:C,3,false)) -> https://assets.roomstogo.com/product/sealy-correct-comfort-bradford-hill-twin-xl-mattress_50028969_alt-image-1
A39: 50028971 | J39: NORTHGATE | K39: TWX NORTHGATE | L39: 977 | M39: 1779 | N39: CORRECT COMFORT | O39: P | R39: Twin XL | S39: Foam | T39: 4-Premier | U39: Side/Back/Stomach | V39: 3-Superior | W39: 3-Superior | X39: Medium | Y39: =IFERROR(VLOOKUP(A39,Sheet3!B:H,6,false),VLOOKUP(J39,Sheet2!A:C,2,false)) -> https://assets.roomstogo.com/product/posturepedic-northgate-twin-xl-mattress_50028971_image-item | Z39: =IFERROR(VLOOKUP(A39,Sheet3!B:H,7,false),VLOOKUP(J39,Sheet2!A:C,3,false)) -> https://assets.roomstogo.com/product/posturepedic-northgate-twin-xl-mattress_50028971_alt-image-1
A40: 50029175 | J40: BRIERWOOD | K40: TWXL BRIERWOOD | L40: 597 | M40: 719 | N40: POSTUREPEDIC | O40: P | P40: The Sealy Posturepedic Briarwood Medium mattress offers lasting comfort and superior support to help maintain natural body alignment and reduce nagging Bed Aches. The orthopedic-inspired Posturepedic Support System features exclusive PrecisionFit Coils, arranged right where you need them. Plus the Coil Edge provides a solid surface that's built to last. | Q40: Adult | R40: Twin XL | S40: Innerspring | T40: 2-Good | U40: Side/Back/Stomach | V40: 2-Good | W40: 2-Good | X40: Medium | Y40: =IFERROR(VLOOKUP(A40,Sheet3!B:H,6,false),VLOOKUP(J40,Sheet2!A:C,2,false)) -> https://assets.roomstogo.com/product/sealy-posturepedic-brierwood-twin-xl-mattress_50029175_image-item | Z40: =IFERROR(VLOOKUP(A40,Sheet3!B:H,7,false),VLOOKUP(J40,Sheet2!A:C,3,false)) -> https://assets.roomstogo.com/product/sealy-posturepedic-brierwood-twin-xl-mattress_50029175_alt-image-1
...

Sheet Formulas sheet
A1: Sku Number | B1: Count of Reviews (posted) | C1: Avg Star Rating | D1: VPC | E1: VPC 1 | F1: VPC 2 | G1: VCP Count of Reviews | H1: VPC Avg Star Rating | I1: Count of 'collection' Reviews | J1: Theme | K1: Intermediate product name | L1: Intermediate product & Size | M1: Customer Description | N1: Sale Price | O1: Regular Price | P1: Specialty Brand | Q1: Proprietary (P) | R1: Collection Copy | S1: Mattress Designation | T1: Mattress Size | U1: Mattress Type | V1: Pressure Relief | W1: Sleep Position | X1: Support Level | Y1: Temperature Management | Z1: Comfort | AA1: Image 1 | AB1: Image 2 | AC1: Base product link | AD1: Actual variant link
A2: 50000543 | J2: CASPER CLOUD ONE | K2: CASPER-CLOUD-ONE | L2: =K2&T2 -> CASPER-CLOUD-ONETwin XL | M2: TWX CASPER CLOUD ONE | N2: 879 | O2: 1099 | P2: CASPER | S2: Adult | T2: Twin XL | U2: Foam | V2: 3-Superior | W2: Side/Back/Stomach | X2: 3-Superior | Y2: 2-Good | Z2: Medium | AA2: =IFERROR(VLOOKUP(A2,Sheet3!B:H,6,false),VLOOKUP(J2,Sheet2!A:C,2,false)) -> https://assets.roomstogo.com/product/casper-cloud-one-twin-xl-mattress_50000543_image-item | AB2: =IFERROR(VLOOKUP(A2,Sheet3!B:H,7,false),VLOOKUP(J2,Sheet2!A:C,3,false)) -> https://assets.roomstogo.com/product/casper-cloud-one-twin-xl-mattress_50000543_alt-image-1 | AC2: ="https://rtg-275.myshopify.com/products/"&K2 -> https://rtg-275.myshopify.com/products/CASPER-CLOUD-ONE | AD2: =vlookup(L2,'Python sheet'!$E$2:$F$373,2,0) -> https://rtg-275.myshopify.com/products/CASPER-CLOUD-ONE?variant=47915101520010
A3: 50000579 | J3: CASPER SNOW 2.0 | K3: CASPER-SNOW-2-0 | L3: =K3&T3 -> CASPER-SNOW-2-0Twin XL | M3: TWXL CASPER SNOW 2.0 | N3: 1595 | O3: 1995 | P3: CASPER | R3: Casper signature cooling hybrid mattress. Specialty cool-to-the-touch fibers give an instantly refreshing feel. Phase Change Materialinstantly pulls heat away whileHeatDeleteT Bandsremove excess body heat to help yousleep 5 cooler all night long. Soothe Memory Foam conforms to the body and gently eases you into deep sleep. Zoned Support helps keep your spine in alignment with firmer foam under the hips, waist and lower back. Individually pocketed Flex Coils reduce motion transfer and boost support. | S3: Adult | T3: Twin XL | U3: Hybrid | V3: 3-Superior | W3: Side/Back/Stomach | X3: 3-Superior | Y3: 4-Premier | Z3: Medium | AA3: =IFERROR(VLOOKUP(A3,Sheet3!B:H,6,false),VLOOKUP(J3,Sheet2!A:C,2,false)) -> https://assets.roomstogo.com/product/casper-snow-20-twin-xl-mattress_50000579_image-item | AB3: =IFERROR(VLOOKUP(A3,Sheet3!B:H,7,false),VLOOKUP(J3,Sheet2!A:C,3,false)) -> https://assets.roomstogo.com/product/casper-snow-20-twin-xl-mattress_50000579_alt-image-1 | AC3: ="https://rtg-275.myshopify.com/products/"&K3 -> https://rtg-275.myshopify.com/products/CASPER-SNOW-2-0 | AD3: =vlookup(L3,'Python sheet'!$E$2:$F$373,2,0) -> https://rtg-275.myshopify.com/products/CASPER-SNOW-2-0?variant=47915101749386
A4: 50000581 | B4: 1 | C4: 5 | D4: Mattress Only~Casper Snow Max | E4: Mattress Only | F4: Casper Snow Max | G4: 380 | H4: 4.42 | I4: 379 | J4: CASPER SNOW MAX | K4: CASPER-SNOW-MAX | L4: =K4&T4 -> CASPER-SNOW-MAXTwin XL | M4: TWXL CASPER SNOW MAX | N4: 2595 | O4: 3245 | P4: CASPER | R4: Ultimate cooling hybrid mattress. Specialty cool-to-the-touch fibers give an instantly refreshing feel. Phase Change MaterialandHeatDeleteT Bands remove excess body heat and help yousleep 6 cooler all night long. Precision-cut foam and encased coils for a breathable and supportive medium-soft feel. Ultra-supportive Align Memory Foam keeps you aligned for your deepest sleep. Firmer center foam cradles your body while giving added support to your hips, waist and lower back. Individually pocketed Flex Coils flex reduce motion transfer and boost support. | S4: Adult | T4: Twin XL | U4: Hybrid | V4: 4-Premier | W4: Side/Back | X4: 3-Superior | Y4: 5-Ultimate | Z4: Soft | AA4: =IFERROR(VLOOKUP(A4,Sheet3!B:H,6,false),VLOOKUP(J4,Sheet2!A:C,2,false)) -> https://assets.roomstogo.com/product/casper-snow-max-twin-xl-mattress_50000581_image-item | AB4: =IFERROR(VLOOKUP(A4,Sheet3!B:H,7,false),VLOOKUP(J4,Sheet2!A:C,3,false)) -> https://assets.roomstogo.com/product/casper-snow-max-twin-xl-mattress_50000581_alt-image-1 | AC4: ="https://rtg-275.myshopify.com/products/"&K4 -> https://rtg-275.myshopify.com/products/CASPER-SNOW-MAX | AD4: =vlookup(L4,'Python sheet'!$E$2:$F$373,2,0) -> https://rtg-275.myshopify.com/products/CASPER-SNOW-MAX?variant=47915101978762
A5: 50000682 | J5: CASPER ONYX 2.0 | K5: CASPER-ONYX-2-0 | L5: =K5&T5 -> CASPER-ONYX-2-0Twin XL | M5: TWXL CASPER ONYX 2.0 | N5: 699 | O5: 799 | P5: CASPER | Q5: P | R5: The Casper Onyx mattress is designed with 3 layers of foam for comfort, breathability and support. Obsessively engineered by Casper's award-winning research and development team, this mattress contains Breathe Flex Foam for support and pressure relief & Breathe Foam for air flow that pairs breathability with softness for all-night comfort. Key FeaturesA cozy knit cover designed with added stretch so you can experience all the comfort your mattress has to offer. Features a top layer of Breathe Flex Foam that's both responsive and breathable to soothe you to sleep with the perfect bit of bounce. A firm Casper Core base provides long-lasting support while preventing sinking and sagging. Foams are certified by the CertiPUR-US program, meaning they are made without ozone depleting chemicals and regulated by the Consumer Product Safety Commission Low VOC Volatile Organic Compound emissions for indoor air quality less than 0.5 parts per million. | S5: Adult | T5: Twin XL | U5: Foam | V5: 2-Good | W5: Side/Back/Stomach | X5: 2-Good | Y5: 2-Good | Z5: Medium | AA5: =IFERROR(VLOOKUP(A5,Sheet3!B:H,6,false),VLOOKUP(J5,Sheet2!A:C,2,false)) -> https://assets.roomstogo.com/product/casper-onyx-20-twin-xl-mattress_50000682_image-item | AB5: =IFERROR(VLOOKUP(A5,Sheet3!B:H,7,false),VLOOKUP(J5,Sheet2!A:C,3,false)) -> https://assets.roomstogo.com/product/casper-onyx-20-twin-xl-mattress_50000682_alt-image-1 | AC5: ="https://rtg-275.myshopify.com/products/"&K5 -> https://rtg-275.myshopify.com/products/CASPER-ONYX-2-0 | AD5: =vlookup(L5,'Python sheet'!$E$2:$F$373,2,0) -> https://rtg-275.myshopify.com/products/CASPER-ONYX-2-0?variant=47915102175370
A6: 50001773 | J6: SMART MATCH 2.0 | K6: SMART-MATCH-2-0 | L6: =K6&T6 -> SMART-MATCH-2-0Twin XL | M6: TWX SMART MATCH 2.0 | N6: 1077 | O6: 3199 | P6: KINGSDOWN | T6: Twin XL | U6: Innerspring | V6: 4-Premier | W6: Side/Back/Stomach | X6: 4-Premier | Y6: 3-Superior | Z6: Medium | AA6: =IFERROR(VLOOKUP(A6,Sheet3!B:H,6,false),VLOOKUP(J6,Sheet2!A:C,2,false)) -> https://assets.roomstogo.com/product/kingsdown-smart-match-20-twin-xl-mattress_50001773_image-item | AB6: =IFERROR(VLOOKUP(A6,Sheet3!B:H,7,false),VLOOKUP(J6,Sheet2!A:C,3,false)) -> https://assets.roomstogo.com/product/kingsdown-smart-match-20-twin-xl-mattress_50001773_alt-image-1 | AC6: ="https://rtg-275.myshopify.com/products/"&K6 -> https://rtg-275.myshopify.com/products/SMART-MATCH-2-0 | AD6: =vlookup(L6,'Python sheet'!$E$2:$F$373,2,0) -> https://rtg-275.myshopify.com/products/SMART-MATCH-2-0?variant=47915102470282
A7: 50007460 | B7: 332 | C7: 4.48 | D7: Mattress Only~Adapt 2.0 Medium | E7: Mattress Only | F7: Adapt 2.0 Medium | G7: 346 | H7: 4.43 | I7: 14 | J7: ADAPT 2.0 MEDIUM | K7: ADAPT-2-0-MEDIUM | L7: =K7&T7 -> ADAPT-2-0-MEDIUMTwin XL | M7: TWXL ADAPT MEDIUM | N7: 1699 | O7: 1699 | P7: TEMPURPEDIC | R7: .Superior cool-to-the-touch feel with a premium knit cover..TEMPUR-Material provides one-of-a-kind, body-conforming support by responding to your body's weight, shape, and temperature to help reduce aches and pains..A second layer of TEMPUR-Material absorbs motion to help minimize disruptions caused by movement from partners, pets, or kids. | S7: Adult | T7: Twin XL | U7: Foam | V7: 4-Premier | W7: Side/Back/Stomach | X7: 4-Premier | Y7: 4-Premier | Z7: Medium | AA7: =IFERROR(VLOOKUP(A7,Sheet3!B:H,6,false),VLOOKUP(J7,Sheet2!A:C,2,false)) -> https://assets.roomstogo.com/product/tempur-pedic-adapt-20-medium-twin-xl-mattress_50007460_image-item | AB7: =IFERROR(VLOOKUP(A7,Sheet3!B:H,7,false),VLOOKUP(J7,Sheet2!A:C,3,false)) -> https://assets.roomstogo.com/product/tempur-pedic-adapt-20-medium-twin-xl-mattress_50007460_alt-image-1 | AC7: ="https://rtg-275.myshopify.com/products/"&K7 -> https://rtg-275.myshopify.com/products/ADAPT-2-0-MEDIUM | AD7: =vlookup(L7,'Python sheet'!$E$2:$F$373,2,0) -> https://rtg-275.myshopify.com/products/ADAPT-2-0-MEDIUM?variant=47915102765194
A8: 50007472 | B8: 2576 | C8: 4.2 | D8: Mattress Only~Adapt 2.0 Medium Hybrid | E8: Mattress Only | F8: Adapt 2.0 Medium Hybrid | G8: 2587 | H8: 4.2 | I8: 11 | J8: ADAPT 2.0 MEDIUM HYBRID | K8: ADAPT-2-0-MEDIUM-HYBRID | L8: =K8&T8 -> ADAPT-2-0-MEDIUM-HYBRIDTwin XL | M8: TWXL ADAPT MEDIUM HYBRID | N8: 1999 | O8: 1999 | P8: TEMPURPEDIC | R8: .Superior cool-to-the-touch feel with a premium knit cover..TEMPUR-Material provides one-of-a-kind, body-conforming support by responding to your body's weight, shape, and temperature to help reduce aches and pains..A second layer of TEMPUR-Material absorbs motion to help minimize disruptions caused by movement from partners, pets, or kids..Hybrid technology combines premium innersprings with TEMPUR-Material to deliver the right combination of pressure relief and support. | S8: Adult | T8: Twin XL | U8: Hybrid | V8: 4-Premier | W8: Side/Back/Stomach | X8: 4-Premier | Y8: 4-Premier | Z8: Medium | AA8: =IFERROR(VLOOKUP(A8,Sheet3!B:H,6,false),VLOOKUP(J8,Sheet2!A:C,2,false)) -> https://assets.roomstogo.com/product/tempur-pedic-adapt-20-medium-hybrid-twin-xl-mattress_50007472_image-item | AB8: =IFERROR(VLOOKUP(A8,Sheet3!B:H,7,false),VLOOKUP(J8,Sheet2!A:C,3,false)) -> https://assets.roomstogo.com/product/tempur-pedic-adapt-20-medium-hybrid-twin-xl-mattress_50007472_alt-image-1 | AC8: ="https://rtg-275.myshopify.com/products/"&K8 -> https://rtg-275.myshopify.com/products/ADAPT-2-0-MEDIUM-HYBRID | AD8: =vlookup(L8,'Python sheet'!$E$2:$F$373,2,0) -> https://rtg-275.myshopify.com/products/ADAPT-2-0-MEDIUM-HYBRID?variant=47915103125642
A9: 50007484 | B9: 237 | C9: 4.6 | D9: Mattress Only~Proadapt 2.0 Firm | E9: Mattress Only | F9: Proadapt 2.0 Firm | G9: 245 | H9: 4.62 | I9: 8 | J9: PROADAPT 2.0 FIRM | K9: PROADAPT-2-0-FIRM | L9: =K9&T9 -> PROADAPT-2-0-FIRMTwin XL | M9: TWXL PROADAPT FIRM | N9: 2899 | O9: 2899 | P9: TEMPURPEDIC | R9: .The removable, machine-washable, and cool-to-the-touch SmartClimate cover features heat-absorbing fibers, drawing heat away from the body for added cooling comfort..Ventilated Advanced Relief Material provides pressure relief and added ventilation for increased airflow..TEMPUR-Material provides one-of-a-kind, body-conforming support by responding to your body's weight, shape, and temperature. | S9: Adult | T9: Twin XL | U9: Foam | V9: 4-Premier | W9: Stomach/Back | X9: 5-Ultimate | Y9: 4-Premier | Z9: Firm | AA9: =IFERROR(VLOOKUP(A9,Sheet3!B:H,6,false),VLOOKUP(J9,Sheet2!A:C,2,false)) -> https://assets.roomstogo.com/product/tempur-pedic-proadapt-20-firm-twin-xl-mattress_50007484_image-item | AB9: =IFERROR(VLOOKUP(A9,Sheet3!B:H,7,false),VLOOKUP(J9,Sheet2!A:C,3,false)) -> https://assets.roomstogo.com/product/tempur-pedic-proadapt-20-firm-twin-xl-mattress_50007484_alt-image-1 | AC9: ="https://rtg-275.myshopify.com/products/"&K9 -> https://rtg-275.myshopify.com/products/PROADAPT-2-0-FIRM | AD9: =vlookup(L9,'Python sheet'!$E$2:$F$373,2,0) -> https://rtg-275.myshopify.com/products/PROADAPT-2-0-FIRM?variant=47915103453322
A10: 50007511 | B10: 302 | C10: 4.48 | D10: Mattress Only~Probreeze 2.0 Medium Hybrid | E10: Mattress Only | F10: Probreeze 2.0 Medium Hybrid | G10: 306 | H10: 4.48 | I10: 4 | J10: PROBREEZE 2.0 MEDIUM HYBRID | K10: PROBREEZE-2-0-MEDIUM-HYBRID | L10: =K10&T10 -> PROBREEZE-2-0-MEDIUM-HYBRIDTwin XL | M10: TWXL PROBREEZE MED HYBRID | N10: 3899 | O10: 3899 | P10: TEMPURPEDIC | R10: Experience all-night cooling with the all-new TEMPUR-ProBreeze mattress. Features a removable, machine-washable cover with heat-absorbing fibers that provide cooling comfort. Premium hybrid technology combines over 1,000 innersprings with Tempur-Pedic's pressure relieving and cooling materials. Delivers exceptional support and ensures cool and comfortable sleep every night. | S10: Adult | T10: Twin XL | U10: Hybrid | V10: 4-Premier | W10: Side/Back/Stomach | X10: 5-Ultimate | Y10: 5-Ultimate | Z10: Medium | AA10: =IFERROR(VLOOKUP(A10,Sheet3!B:H,6,false),VLOOKUP(J10,Sheet2!A:C,2,false)) -> https://assets.roomstogo.com/product/tempur-pedic-probreeze-20-medium-hybrid-twin-xl-mattress_50007511_image-item | AB10: =IFERROR(VLOOKUP(A10,Sheet3!B:H,7,false),VLOOKUP(J10,Sheet2!A:C,3,false)) -> https://assets.roomstogo.com/product/tempur-pedic-probreeze-20-medium-hybrid-twin-xl-mattress_50007511_image-item | AC10: ="https://rtg-275.myshopify.com/products/"&K10 -> https://rtg-275.myshopify.com/products/PROBREEZE-2-0-MEDIUM-HYBRID | AD10: =vlookup(L10,'Python sheet'!$E$2:$F$373,2,0) -> https://rtg-275.myshopify.com/products/PROBREEZE-2-0-MEDIUM-HYBRID?variant=47915104043146
A11: 50007523 | B11: 5214 | C11: 4.27 | D11: Mattress Only~Proadapt 2.0 Medium | E11: Mattress Only | F11: Proadapt 2.0 Medium | G11: 5219 | H11: 4.27 | I11: 5 | J11: PROADAPT 2.0 MEDIUM | K11: PROADAPT-2-0-MEDIUM | L11: =K11&T11 -> PROADAPT-2-0-MEDIUMTwin XL | M11: TWXL PROADAPT MEDIUM | N11: 2899 | O11: 2899 | P11: TEMPURPEDIC | R11: .The removable, machine-washable, and cool-to-the-touch SmartClimate cover features heat-absorbing fibers, drawing heat away from the body for added cooling comfort..Ventilated Advanced Relief Material provides pressure relief and added ventilation for increased airflow..TEMPUR-Material provides one-of-a-kind, body-conforming support by responding to your body's weight, shape, and temperature. | S11: Adult | T11: Twin XL | U11: Foam | V11: 4-Premier | W11: Side/Back/Stomach | X11: 5-Ultimate | Y11: 4-Premier | Z11: Medium | AA11: =IFERROR(VLOOKUP(A11,Sheet3!B:H,6,false),VLOOKUP(J11,Sheet2!A:C,2,false)) -> https://assets.roomstogo.com/product/tempur-pedic-proadapt-20-medium-twin-xl-mattress_50007523_image-item | AB11: =IFERROR(VLOOKUP(A11,Sheet3!B:H,7,false),VLOOKUP(J11,Sheet2!A:C,3,false)) -> https://assets.roomstogo.com/product/tempur-pedic-proadapt-20-medium-twin-xl-mattress_50007523_alt-image-1 | AC11: ="https://rtg-275.myshopify.com/products/"&K11 -> https://rtg-275.myshopify.com/products/PROADAPT-2-0-MEDIUM | AD11: =vlookup(L11,'Python sheet'!$E$2:$F$373,2,0) -> https://rtg-275.myshopify.com/products/PROADAPT-2-0-MEDIUM?variant=47915104305290
A12: 50007535 | B12: 72 | C12: 4.31 | D12: Mattress Only~Proadapt 2.0 Soft | E12: Mattress Only | F12: Proadapt 2.0 Soft | G12: 77 | H12: 4.19 | I12: 5 | J12: PROADAPT 2.0 SOFT | K12: PROADAPT-2-0-SOFT | L12: =K12&T12 -> PROADAPT-2-0-SOFTTwin XL | M12: TWXL PROADAPT SOFT | N12: 2899 | O12: 2899 | P12: TEMPURPEDIC | R12: .The removable, machine-washable, and cool-to-the-touch SmartClimate cover features heat-absorbing fibers, drawing heat away from the body for added cooling comfort..Specially ventilated TEMPUR-Material delivers additional airflow and breathability, while providing pressure relief and motion absorption..Advanced Relief Material is the most pressure-relieving material made by Tempur-Pedic and conforms to your body for ultimate comfort. | S12: Adult | T12: Twin XL | U12: Foam | V12: 5-Ultimate | W12: Side/Back | X12: 5-Ultimate | Y12: 4-Premier | Z12: Soft | AA12: =IFERROR(VLOOKUP(A12,Sheet3!B:H,6,false),VLOOKUP(J12,Sheet2!A:C,2,false)) -> https://assets.roomstogo.com/product/tempur-pedic-proadapt-20-soft-twin-xl-mattress_50007535_image-item | AB12: =IFERROR(VLOOKUP(A12,Sheet3!B:H,7,false),VLOOKUP(J12,Sheet2!A:C,3,false)) -> https://assets.roomstogo.com/product/tempur-pedic-proadapt-20-soft-twin-xl-mattress_50007535_alt-image-1 | AC12: ="https://rtg-275.myshopify.com/products/"&K12 -> https://rtg-275.myshopify.com/products/PROADAPT-2-0-SOFT | AD12: =vlookup(L12,'Python sheet'!$E$2:$F$373,2,0) -> https://rtg-275.myshopify.com/products/PROADAPT-2-0-SOFT?variant=47915104567434
A13: 50007559 | B13: 960 | C13: 4.38 | D13: Mattress Only~Proadapt 2.0 Medium Hybrid | E13: Mattress Only | F13: Proadapt 2.0 Medium Hybrid | G13: 975 | H13: 4.38 | I13: 15 | J13: PROADAPT 2.0 MEDIUM HYBRID | K13: PROADAPT-2-0-MEDIUM-HYBRID | L13: =K13&T13 -> PROADAPT-2-0-MEDIUM-HYBRIDTwin XL | M13: TWXL PROADAPT MEDIUM HYBRID | N13: 2899 | O13: 2899 | P13: TEMPURPEDIC | R13: .The removable, machine-washable, and cool-to-the-touch SmartClimate cover features heat-absorbing fibers, drawing heat away from the body for added cooling comfort..Specially ventilated TEMPUR-Material delivers additional airflow and breathability, while providing pressure relief and motion absorption..Advanced Relief Material is the most pressure-relieving material made by Tempur-Pedic and contours to your body for ultimate comfort. .Hybrid technology mixes premium innersprings with one-of-a-kind Tempur-Pedic materials to deliver the right combination of relief and support. | S13: Adult | T13: Twin XL | U13: Hybrid | V13: 4-Premier | W13: Side/Back/Stomach | X13: 5-Ultimate | Y13: 4-Premier | Z13: Medium | AA13: =IFERROR(VLOOKUP(A13,Sheet3!B:H,6,false),VLOOKUP(J13,Sheet2!A:C,2,false)) -> https://assets.roomstogo.com/product/tempur-pedic-proadapt-20-medium-hybrid-twin-xl-mattress_50007559_image-item | AB13: =IFERROR(VLOOKUP(A13,Sheet3!B:H,7,false),VLOOKUP(J13,Sheet2!A:C,3,false)) -> https://assets.roomstogo.com/product/tempur-pedic-proadapt-20-medium-hybrid-twin-xl-mattress_50007559_alt-image-1 | AC13: ="https://rtg-275.myshopify.com/products/"&K13 -> https://rtg-275.myshopify.com/products/PROADAPT-2-0-MEDIUM-HYBRID | AD13: =vlookup(L13,'Python sheet'!$E$2:$F$373,2,0) -> https://rtg-275.myshopify.com/products/PROADAPT-2-0-MEDIUM-HYBRID?variant=47915104895114
A14: 50007561 | B14: 1233 | C14: 4.24 | D14: Mattress Only~Luxeadapt 2.0 Soft | E14: Mattress Only | F14: Luxeadapt 2.0 Soft | G14: 1234 | H14: 4.24 | I14: 1 | J14: LUXEADAPT 2.0 SOFT | K14: LUXEADAPT-2-0-SOFT | L14: =K14&T14 -> LUXEADAPT-2-0-SOFTTwin XL | M14: TWXL LUXEADAPT SOFT | N14: 4199 | O14: 4199 | P14: TEMPURPEDIC | R14: .The removable, machine-washable, and cool-to-the-touch SmartClimate cover features heat-absorbing fibers, drawing heat away from the body for added cooling comfort..Specially ventilated TEMPUR-Material delivers additional airflow and breathability, while providing pressure relief and motion absorption..Advanced Relief Material is the most pressure-relieving material made by Tempur-Pedic and contours to your body for ultimate comfort. .An ergonomic 5-zone support layer conforms to your body for targeted support in the spine, hips, and shoulders for personalized comfort. | S14: Adult | T14: Twin XL | U14: Foam | V14: 5-Ultimate | W14: Side/Back | X14: 5-Ultimate | Y14: 4-Premier | Z14: Soft | AA14: =IFERROR(VLOOKUP(A14,Sheet3!B:H,6,false),VLOOKUP(J14,Sheet2!A:C,2,false)) -> https://assets.roomstogo.com/product/tempur-pedic-luxeadapt-20-soft-twin-xl-mattress_50007561_image-item | AB14: =IFERROR(VLOOKUP(A14,Sheet3!B:H,7,false),VLOOKUP(J14,Sheet2!A:C,3,false)) -> https://assets.roomstogo.com/product/tempur-pedic-luxeadapt-20-soft-twin-xl-mattress_50007561_alt-image-1 | AC14: ="https://rtg-275.myshopify.com/products/"&K14 -> https://rtg-275.myshopify.com/products/LUXEADAPT-2-0-SOFT | AD14: =vlookup(L14,'Python sheet'!$E$2:$F$373,2,0) -> https://rtg-275.myshopify.com/products/LUXEADAPT-2-0-SOFT?variant=47915105157258
A15: 50007585 | B15: 125 | C15: 4.61 | D15: Mattress Only~Luxeadapt 2.0 Medium Hybrid | E15: Mattress Only | F15: Luxeadapt 2.0 Medium Hybrid | G15: 129 | H15: 4.62 | I15: 4 | J15: LUXEADAPT 2.0 MEDIUM HYBRID | K15: LUXEADAPT-2-0-MEDIUM-HYBRID | L15: =K15&T15 -> LUXEADAPT-2-0-MEDIUM-HYBRIDTwin XL | M15: TWXL LUXEADAPT MEDIUM HYBRID | N15: 4199 | O15: 4199 | P15: TEMPURPEDIC | R15: .The removable, machine-washable, and cool-to-the-touch SmartClimate cover features heat-absorbing fibers, drawing heat away from the body for added cooling comfort..Specially ventilated TEMPUR-Material delivers additional airflow and breathability, while providing pressure relief and motion absorption..Advanced Relief Material is the most pressure-relieving material made by Tempur-Pedic and contours to your body for ultimate comfort. .Hybrid technology mixes premium innersprings with a proprietary hybrid material to deliver a lighter, more-responsive feel that helps support any sleep position. | S15: Adult | T15: Twin XL | U15: Hybrid | V15: 5-Ultimate | W15: Side/Back/Stomach | X15: 5-Ultimate | Y15: 4-Premier | Z15: Medium | AA15: =IFERROR(VLOOKUP(A15,Sheet3!B:H,6,false),VLOOKUP(J15,Sheet2!A:C,2,false)) -> https://assets.roomstogo.com/product/tempur-pedic-luxeadapt-20-medium-hybrid-twin-xl-mattress_50007585_image-item | AB15: =IFERROR(VLOOKUP(A15,Sheet3!B:H,7,false),VLOOKUP(J15,Sheet2!A:C,3,false)) -> https://assets.roomstogo.com/product/tempur-pedic-luxeadapt-20-medium-hybrid-twin-xl-mattress_50007585_alt-image-1 | AC15: ="https://rtg-275.myshopify.com/products/"&K15 -> https://rtg-275.myshopify.com/products/LUXEADAPT-2-0-MEDIUM-HYBRID | AD15: =vlookup(L15,'Python sheet'!$E$2:$F$373,2,0) -> https://rtg-275.myshopify.com/products/LUXEADAPT-2-0-MEDIUM-HYBRID?variant=47915105386634
